Workbook

Sheet 设备型号
A1: 电加热器 | F1: SGS | K1: 变压器
A2: 序号 | B2: 电加热器功率型号 | C2: 单位 | D2: 备注 | F2: 序号 | G2: SGS功率型号 | H2: 单位 | I2: 备注 | K2: 序号 | L2: 变压器型号 | M2: 单位 | N2: 备注
A3: 1 | B3: 5 | C3: MW | D3: 电加热器功率范围5-30MW，每5MW为1个型号 | F3: 1 | G3: 5 | H3: MW | I3: SGS功率根据实际计算值向上取整至5的倍数 | K3: 1 | L3: 6.3 | M3: MVA | N3: 根据电加热器功率向上取值，若电加热器功率高于变压器最大容量，可通过多台变压器组合
A4: 2 | B4: 10 | C4: MW | F4: 2 | G4: 10 | H4: MW | K4: 2 | L4: 8 | M4: MVA
A5: 3 | B5: 15 | C5: MW | F5: 3 | G5: 15 | H5: MW | K5: 3 | L5: 10 | M5: MVA
A6: 4 | B6: 20 | C6: MW | F6: 4 | G6: 20 | H6: MW | K6: 4 | L6: 12.5 | M6: MVA
A7: 5 | B7: 25 | C7: MW | F7: 5 | G7: 25 | H7: MW | K7: 5 | L7: 16 | M7: MVA
A8: 6 | B8: 30 | C8: MW | F8: 6 | G8: 30 | H8: MW | K8: 6 | L8: 20 | M8: MVA
F9: 7 | G9: 35 | H9: MW | K9: 7 | L9: 25 | M9: MVA
F10: 8 | G10: 40 | H10: MW | K10: 8 | L10: 31.5 | M10: MVA
A11: 热泵 | F11: 9 | G11: 45 | H11: MW | K11: 9 | L11: 40 | M11: MVA
A12: 序号 | B12: 热泵热功率型号 | C12: 单位 | D12: 备注 | F12: 10 | G12: …… | H12: MW | K12: 10 | L12: 50 | M12: MVA
A13: 1 | B13: 5 | C13: MWt | D13: 热泵热功率范围5-80MW，每5MW为1个型号 | K13: 11 | L13: 63 | M13: MVA
A14: 2 | B14: 10 | C14: MWt | K14: 12 | L14: 90 | M14: MVA
A15: 3 | B15: 15 | C15: MWt | K15: 13 | L15: 120 | M15: MVA
A16: 4 | B16: 20 | C16: MWt
A17: 5 | B17: …… | C17: MWt
A18: 6 | B18: 70 | C18: MWt
A19: 7 | B19: 75 | C19: MWt
A20: 8 | B20: 80 | C20: MWt

Sheet 熔盐参数
B1: HITEC熔盐 | H1: 太阳盐
B2: 序号 | C2: 项目 | D2: 单位 | E2: 参数 | F2: 备注 | H2: 序号 | I2: 项目 | J2: 单位 | K2: 参数 | L2: 备注
B3: 1 | C3: 高温熔盐温度 | D3: ℃ | E3: 390 | F3: 输入值 | H3: 1 | I3: 高温熔盐温度 | J3: ℃ | K3: 565 | L3: 输入值
B4: 2 | C4: 低温熔盐温度 | D4: ℃ | E4: 190 | F4: 输入值 | H4: 2 | I4: 低温熔盐温度 | J4: ℃ | K4: 290 | L4: 输入值
B5: 3 | C5: 高温熔盐密度 | D5: kg/m3 | E5: =0.0003602*E3^2-0.9721*E3+2115 -> 1790.6674 | H5: 3 | I5: 高温熔盐密度 | J5: kg/m3 | K5: =2090-0.636*K3 -> 1730.66
B6: 4 | C6: 低温熔盐密度 | D6: kg/m3 | E6: =0.0003602*E4^2-0.9721*E4+2115 -> 1943.3042 | H6: 4 | I6: 低温熔盐密度 | J6: kg/m3 | K6: =2090-0.636*K4 -> 1905.56
B7: 5 | C7: 高温熔盐导热系数 | D7: kcal/(m·h·℃) | E7: =3.283*10^-9*E3^3-4.02*10^-6*E3^2+0.00104*E3+0.3015 -> 0.29040228 | H7: 5 | I7: 高温熔盐导热系数 | J7: kcal/(m·h·℃) | K7: =0.443+1.9*K3/10^4 -> 0.55035
B8: 6 | C8: 低温熔盐导热系数 | D8: kcal/(m·h·℃) | E8: =3.283*10^-9*E4^3-4.02*10^-6*E4^2+0.00104*E4+0.3015 -> 0.3764961 | H8: 6 | I8: 低温熔盐导热系数 | J8: kcal/(m·h·℃) | K8: =0.443+1.9*K4/10^4 -> 0.4981
B9: 7 | C9: 高温熔盐粘度 | D9: (kg·s)/m2 | E9: =5.771*10^7*E3^-3.001+0.9426 -> 1.9096884 | H9: 7 | I9: 高温熔盐粘度 | J9: (kg·s)/m2 | K9: =22.714-0.12*K3+2.281*K3^2/10^4-1.474*K3^3/10^7 -> 1.1438453
B10: 8 | C10: 低温熔盐粘度 | D10: (kg·s)/m2 | E10: =5.771*10^7*E4^-3.001+0.9426 -> 9.3123313 | H10: 8 | I10: 低温熔盐粘度 | J10: (kg·s)/m2 | K10: =22.714-0.12*K4+2.281*K4^2/10^4-1.474*K4^3/10^7 -> 3.5022714
B11: 9 | C11: 高温熔盐焓值 | D11: kJ/kg/℃ | E11: =1.42 -> 1.42 | H11: 9 | I11: 高温熔盐比热 | J11: kJ/kg/℃ | K11: =(1443+0.172*K3)/1000 -> 1.54018
B12: 10 | C12: 低温熔盐焓值 | D12: kJ/kg/℃ | E12: =1.42 -> 1.42 | H12: 10 | I12: 低温熔盐比热 | J12: kJ/kg/℃ | K12: =(1443+0.172*K4)/1000 -> 1.49288

Sheet 输入
A1: 序号 | B1: 名称 | C1: 单位 | D1: 参数 | E1: 备注 | F1: 项目信息
A2: 1 | B2: 蒸汽压力 | C2: MPa | D2: 1.5 | F2: 该项目为谷电熔盐储热供蒸汽项目，电加热器/热泵消纳谷电，将熔盐加热储存，储热时长8h，在白天通过熔盐SGS供应8h蒸汽
A3: 2 | B3: 蒸汽温度 | C3: ℃ | D3: 200
A4: 3 | B4: 蒸汽流量 | C4: t/h | D4: 100
A5: 4 | B5: 给水压力 | C5: MPa | D5: 0.1
A6: 5 | B6: 给水温度 | C6: ℃ | D6: 20
A7: 6 | B7: 供汽时长 | C7: h | D7: 8
A8: 7 | B8: 谷电时长 | C8: h | D8: 8
A9: 8 | B9: 运行天数 | C9: d | D9: 330
A10: 9 | B10: 电加热器电热效率 | C10: / | D10: 0.985
A11: 10 | B11: 余热温度 | C11: ℃ | D11: 30
A12: 11 | B12: 热泵cop | C12: / | D12: 1.3 | E12: 根据余热温度确定
A13: 12 | B13: 换热效率 | C13: / | D13: 0.99
A14: 13 | B14: 储热效率 | C14: / | D14: 0.99

Sheet 计算
A1: 电加热器 | G1: 热泵
A2: 序号 | B2: 名称 | C2: 单位 | D2: 参数 | E2: 备注 | G2: 序号 | H2: 名称 | I2: 单位 | J2: 参数 | K2: 备注
A3: 1 | B3: 蒸汽焓值 | C3: kJ/kg | D3: {=[1]!enthalpy("water","PT","SI with C",输入!D2,输入!D3)} -> 2795.9839 | E3: 根据蒸汽压力、温度计算焓值 | G3: 1 | H3: 蒸汽焓值 | I3: kJ/kg | J3: {=[1]!enthalpy("water","PT","SI with C",输入!D2,输入!D3)} -> 2795.9839 | K3: 根据蒸汽压力、温度计算焓值
A4: 2 | B4: 给水焓值 | C4: kJ/kg | D4: {=[1]!enthalpy("water","PT","SI with C",输入!D5,输入!D6)} -> 84.006054 | E4: 根据给水压力、温度计算焓值 | G4: 2 | H4: 给水焓值 | I4: kJ/kg | J4: {=[1]!enthalpy("water","PT","SI with C",输入!D5,输入!D6)} -> 84.006054 | K4: 根据给水压力、温度计算焓值
A5: 3 | B5: SGS功率 | C5: MW | D5: =输入!D4*(计算!D3-计算!D4)/3600 -> 75.332719 | E5: 根据蒸汽流量、进出口焓差计算 | G5: 3 | H5: SGS功率 | I5: MW | J5: =输入!D4*(J3-J4)/3600 -> 75.332719 | K5: 根据蒸汽流量、进出口焓差计算
A6: 4 | B6: 制热量 | C6: MWh | D6: =D5*输入!D7/输入!D13 -> 608.74924 | E6: 根据SGS功率、供汽时长计算 | G6: 4 | H6: 制热量 | I6: MWh | J6: =J5*输入!D7/输入!D13 -> 608.74924 | K6: 根据SGS功率、供汽时长计算
A7: 5 | B7: 电加热器功率 | C7: MW | D7: =D6/输入!D8/输入!D10 -> 77.252442 | E7: 根据制热量、谷电时长计算 | G7: 5 | H7: 热泵热功率 | I7: MWt | J7: =J6/输入!D8 -> 76.093655 | K7: 根据制热量、谷电时长计算
A8: 6 | B8: 储热量 | C8: MWh | D8: =D6/输入!D14 -> 614.89822 | E8: 根据制热量计算 | G8: 6 | H8: 热泵电功率 | I8: MW | J8: =J6/输入!D8/输入!D12 -> 58.533581 | K8: 根据cop计算
A9: 7 | B9: 年用电量 | C9: 万kWh | D9: =D7*输入!D8*输入!D9/10 -> 20394.645 | G9: 7 | H9: 储热量 | I9: MWh | J9: =J6/输入!D14 -> 614.89822 | K9: 根据制热量计算
A10: 8 | B10: 年供汽量 | C10: 万t | D10: =输入!D4*输入!D8*输入!D9/10000 -> 26.4 | G10: 8 | H10: 年用电量 | I10: 万kWh | J10: =J8*输入!D8*输入!D9/10 -> 15452.865
G11: 9 | H11: 年供汽量 | I11: 万t | J11: =输入!D4*输入!D7*输入!D9/10000 -> 26.4

Sheet 选型
A1: 序号 | B1: 名称 | C1: 单位 | D1: 参数 | E1: 备注
A2: 1 | B2: 电加热器 | C2: MW | D2: =ROUNDUP(计算!D7,-1) -> 80 | E2: 电加热器方案
B3: 热泵 | C3: MWt | D3: =ROUNDUP(计算!J7,-1) -> 80 | E3: 热泵方案
A4: 2 | B4: 储热量 | C4: MWh | D4: =ROUNDUP(计算!D8,-1) -> 620
A5: 3 | B5: 熔盐类型 | C5: / | D5: HITEC熔盐 | E5: HITEC熔盐使用温区190-400℃以内，太阳盐使用温区290-565℃以内，根据蒸汽参数计算热平衡确定熔盐类型和使用温区，需要注意熔盐和蒸汽换热时的夹点问题
A6: 4 | B6: 高温熔盐温度 | C6: ℃ | D6: 390
A7: 5 | B7: 低温熔盐温度 | C7: ℃ | D7: 190
A8: 6 | B8: 熔盐比热 | C8: kJ/kg/k | D8: =1.42 -> 1.42 | E8: 根据熔盐类型确定
A9: 7 | B9: 熔盐量 | C9: t | D9: =ROUNDUP(D4*3600/D8/(D6-D7)*1.1,-1) -> 8650
A10: 8 | B10: SGS功率 | C10: MW | D10: =ROUNDUP(计算!D5,0) -> 76
A11: 9 | B11: 变压器容量 | C11: MVA | D11: {=_xlfn.IFS(计算!D7<=16,16,计算!D7<=20,20,计算!D7<=25,25,计算!D7<=31.5,31.5,计算!D7<=40,40,计算!D7<=50,50,计算!D7<=63,63,计算!D7<=90,90,计算!D7<=120,120)} -> 90 | E11: 电加热器方案 | F11: 根据用电功率选择变压器容量，电加热器功率因数按1，热泵功率因数按0.85
D12: {=_xlfn.IFS(ROUNDUP(计算!J8/0.85,0)<=16,16,ROUNDUP(计算!J8/0.85,0)<=20,20,ROUNDUP(计算!J8/0.85,0)<=25,25,ROUNDUP(计算!J8/0.85,0)<=31.5,31.5,ROUNDUP(计算!J8/0.85,0)<=40,40,ROUNDUP(计算!J8/0.85,0)<=50,50,ROUNDUP(计算!J8/0.85,0)<=63,63,ROUNDUP(计算!J8/0.85,0)<=90,90,ROUNDUP(计算!J8/0.85,0)<=120,120)} -> 90 | E12: 热泵方案

Sheet 造价
A1: 电加热器
A2: 序号 | B2: 名称 | C2: 单位 | D2: 单位造价 | E2: 总价 | F2: 备注
A3: 1 | B3: 电加热器 | C3: 万元 | D3: =IF(选型!D2<100,40,IF(选型!D2<200,38,35)) -> 40 | E3: =D3*选型!D2 -> 3200 | F3: 40万/MW
A4: 2 | B4: 储热系统 | C4: 万元 | D4: =IF(选型!D9<10000,1.2,IF(选型!D9<20000,1.1,1)) -> 1.2 | E4: =D4*选型!D9 -> 10380 | F4: 根据盐量确定，1万吨以下取1.2，2万吨以下取1.1，2万吨以上取1
A5: 3 | B5: 换热系统 | C5: 万元 | D5: =IF(选型!D10<250,35,IF(选型!D10<350,32,30)) -> 35 | E5: =D5*选型!D10 -> 2660 | F5: 35万/MW
A6: 4 | B6: 电气系统 | C6: 万元 | D6: 12 | E6: =D6*选型!D11 -> 1080 | F6: 12万/MW
A7: 5 | B7: 设备投资 | C7: 万元 | D7: / | E7: =SUM(E3:E6) -> 17320
A8: 6 | B8: 建设及备用 | C8: 万元 | E8: =E9-E7 -> 4330 | F8: 总投资减设备投资
A9: 7 | B9: 总投资 | C9: 万元 | E9: =E7/0.8 -> 21650 | F9: 按设备投资占总投资的80%反算
A11: 热泵
A12: 序号 | B12: 名称 | C12: 单位 | D12: 单位造价 | E12: 总价 | F12: 备注
A13: 1 | B13: 热泵 | C13: 万元 | D13: =IF(选型!D3<150,IF(输入!D11<50,94,80),IF(输入!D11<50,85,73)) -> 94 | E13: =D13*选型!D3 -> 7520 | F13: 80万/MW
A14: 2 | B14: 储热系统 | C14: 万元 | D14: =IF(选型!D9<10000,1.2,IF(选型!D9<20000,1.1,1)) -> 1.2 | E14: =D14*选型!D9 -> 10380 | F14: 根据盐量确定，1万吨以下取1.2，2万吨以下取1.1，2万吨以上取1
A15: 3 | B15: 换热系统 | C15: 万元 | D15: 35 | E15: =D15*选型!D10 -> 2660 | F15: 35万/MW
A16: 4 | B16: 电气系统 | C16: 万元 | D16: 12 | E16: =D16*选型!D12 -> 1080 | F16: 12万/MW
A17: 5 | B17: 设备投资 | C17: 万元 | D17: / | E17: =SUM(E13:E16) -> 21640
A18: 6 | B18: 建设及备用 | C18: 万元 | E18: =E19-E17 -> 5410 | F18: 总投资减设备投资
A19: 7 | B19: 总投资 | C19: 万元 | E19: =E17/0.8 -> 27050 | F19: 按设备投资占总投资的80%反算

Sheet 工程概算
A1: 序号 | B1: 工程或费用名称 | C1: 建筑工程费 | D1: 设备购置费 | E1: 安装工程费 | F1: 其他费用 | G1: 合计:万元 | H1: 备注
A2: 一 | B2: 主辅生产工程 | C2: =SUM(C3:C10) -> 2936.0182 | D2: =SUM(D3:D10) -> 14334.872 | E2: =SUM(E3:E10) -> 2303.1936 | G2: =C2+D2+E2+F2 -> 19574.083
A3: 1 | B3: 储能系统（含熔盐管道） | C3: =G3*1155/(26133-2417) -> 505.51948 | D3: =G3*(22505-2417)/(26133-2417) -> 8792.0998 | E3: =G3*2473/(26133-2417) -> 1082.3807 | G3: =造价!E4 -> 10380
A4: 2 | B4: 蒸汽发生系统（含蒸汽管道） | C4: =G4/7352*1773 -> 641.48259 | D4: =G4/7352*4349 -> 1573.4956 | E4: =G4/7352*1230 -> 445.02176 | G4: =造价!E5 -> 2660 | K4: 建筑工程费 | L4: 设备购置费 | M4: 安装工程费 | N4: 合计
A5: 3 | B5: 电加热系统 | D5: =G5 -> 3200 | G5: =造价!E3 -> 3200 | J5: 热泵系统 | K5: =N5/1.21*0.14 -> 870.08264 | L5: =N5/1.21*1 -> 6214.876 | M5: =N5/1.21*0.07 -> 435.04132 | N5: =造价!E13 -> 7520
A6: 4 | B6: 热力系统 | C6: =G6/13499*2608 -> 0 | D6: =G6/13499*7812 -> 0 | E6: =G6/13499*3079 -> 0 | G6: 0
A7: 5 | B7: 水处理系统 | C7: =G7/3168*1351 -> 0 | D7: =G7/3168*1616 -> 0 | E7: =G7/3168*201 -> 0 | G7: 0
A8: 6 | B8: 供水系统 | C8: =G8/7646*1969 -> 0 | D8: =G8/7646*3704 -> 0 | E8: =G8/7646*1973 -> 0 | G8: 0
A9: 7 | B9: 电气控制系统 | C9: =G9/12286*1120 -> 98.453524 | D9: =G9/12286*6187 -> 543.86782 | E9: =G9/12286*4979 -> 437.67866 | G9: =造价!E6 -> 1080
A10: 8 | B10: 其他辅助系统 | C10: =G10*0.75 -> 1690.5626 | D10: =G10*0.1 -> 225.40835 | E10: =G10*0.15 -> 338.11252 | G10: 2254.0835
A11: 二 | B11: 其他费用 | F11: =SUM(F12:F16) -> 1488.694 | G11: =F11 -> 1488.694
A12: 1 | B12: 建设场地征用及清理费 | F12: 100 | G12: =SUM(C12:F12) -> 100
A13: 2 | B13: 项目建设管理费 | F13: =C31 -> 610.99979 | G13: =SUM(C13:F13) -> 610.99979
A14: 3 | B14: 项目建设技术服务费 | F14: =C38 -> 504.60034 | G14: =SUM(C14:F14) -> 504.60034
A15: 4 | B15: 整套启动试运费 | F15: =C46 -> 120 | G15: =SUM(C15:F15) -> 120
A16: 5 | B16: 生产准备费 | F16: =C47 -> 153.0939 | G16: =SUM(C16:F16) -> 153.0939
A17: 6 | B17: 大件运输措施费（设备运费） | G17: =SUM(C17:F17) -> 0
A18: 三 | B18: 基本预备费 | F18: =G2*0.03 -> 587.2225 | G18: =SUM(C18:F18) -> 587.2225
B19: 工程静态投资 | C19: =C2+C11+C18 -> 2936.0182 | D19: =D2+D11+D18 -> 14334.872 | E19: =E2+E11+E18 -> 2303.1936 | F19: =F2+F11+F18 -> 2075.9165 | G19: =SUM(C19:F19) -> 21650 | H19: 保证静态投资与造价中的总投资一致 | I19: =G19-造价!E9 -> 0
B20: 各类费用占静态投资 | C20: =C19/G19 -> 0.13561285 | D20: =D19/G19 -> 0.66211878 | E20: =E19/G19 -> 0.10638308 | F20: =F19/G19 -> 0.09588529 | G20: =SUM(C20:F20) -> 1
A21: 四 | B21: 建设期贷款利息 | F21: =1000 -> 1000 | G21: =SUM(C21:F21) -> 1000 | H21: 根据工程静态投资、贷款利率、建设期计算
A22: 五 | B22: 工程动态投资 | C22: =C19 -> 2936.0182 | D22: =D19 -> 14334.872 | E22: =E19 -> 2303.1936 | F22: =F19+F21 -> 3075.9165 | G22: =SUM(C22:F22) -> 22650
B23: 其中：可抵扣固定资产增值税额 | C23: =C22/1.09*0.09 -> 242.42352 | D23: =D22/1.13*0.13 -> 1649.1445 | E23: =E22/1.09*0.09 -> 190.17195 | F23: =F22/1.02*0.015 -> 45.234067 | G23: =SUM(C23:F23) -> 2126.9741
A24: 六 | B24: 可计入固定资产 | C24: =C22-C23 -> 2693.5947 | D24: =D22-D23 -> 12685.727 | E24: =E22-E23 -> 2113.0217 | F24: =F22-F23 -> 3030.6825 | G24: =SUM(C24:F24) -> 20523.026
B25: 铺底流动资金
A29: 其他费用估算
A30: 序号 | B30: 费用名称 | C30: 数值 | D30: 备注
A31: 1 | B31: 项目管理费 | C31: =SUM(C32:C37) -> 610.99979 | D31: 公式计算
A32: 1.1 | B32: 法人管理费 | C32: =(C2+E2)*7.07% -> 370.41227
A33: 1.2 | B33: 招标费 | C33: =G2*0.35% -> 68.509292
A34: 1.3 | B34: 工程监理费 | C34: =(C2+E2)*1.55% -> 81.207783
A35: 1.4 | B35: 设备材料建造费 | C35: =(D2+(C2+E2)*0.4)*0.3% -> 49.291669
A36: 1.5 | B36: 造价咨询及竣工结算审核 | C36: =(C2+E2)*0.42% -> 22.00469
A37: 1.6 | B37: 工程保险费 | C37: =G2*0.1% -> 19.574083
A38: 2 | B38: 项目技术服务费 | C38: =SUM(C39:C45) -> 504.60034
A39: 2.1 | B39: 项目前期工作费 | C39: 30 | D39: 参照金塔
A40: 2.2 | B40: 设备成套技术服务费 | C40: =D2*0.15% -> 21.502307 | D40: 公式计算
A41: 2.3 | B41: 勘察设计费 | C41: 400 | D41: 参照金塔
A42: 2.4 | B42: 设计文件评审费 | C42: 15 | D42: 参照金塔
A43: 2.5 | B43: 项目后评价费 | C43: =(C2+E2)*0.15% -> 7.8588177 | D43: 公式计算
...
